Workbook
Name NativeTimeline_Disbursement_Date: #N/A
Name Slicer_City: #N/A
Name Slicer_Loan_Purpose: #N/A
Name Slicer_Loan_Status: #N/A

Sheet Raw Data
A1: Loan_ID | B1: Customer_ID | C1: Age | D1: Gender | E1: City | F1: Employment_Type | G1: Monthly_Income | H1: Loan_Amount | I1: Loan_Tenure_Months | J1: Interest_Rate | K1: EMI_Amount | L1: Loan_Purpose | M1: Loan_Status | N1: Disbursement_Date | O1: Closure_Date | P1: Days_to_Close | Q1: Credit_Score | R1: DPD_30 | S1: Recovery_Amount | T1: Disbursment Month | U1: Default Interest Rate
A2: LN0001 | B2: CU2824 | C2: 22 | D2: Female | E2: Mumbai | F2: Salaried | G2: 51579 | H2: 391123 | I2: 3 | J2: 28.24 | K2: 136558.19 | L2: Business | M2: Active | N2: 45166 | Q2: 732 | R2: Yes | S2: 0 | T2: Aug-23 | U2: =COUNTIF(Table1[Loan_Status],"Defaulted")/COUNTA(Table1[Loan_ID]) -> 0.248
A3: LN0002 | B3: CU2535 | C3: 34 | D3: Male | E3: Chennai | F3: Salaried | G3: 67124 | H3: 380400 | I3: 24 | J3: 22.07 | K3: 19747.6 | L3: Shopping | M3: Defaulted | N3: 44568 | Q3: 463 | R3: Yes | S3: 223940.56 | T3: Jan-22 | U3: =COUNTIF(Table1[Loan_Status],"Defaulted")/COUNTA(Table1[Loan_ID]) -> 0.248
A4: LN0003 | B4: CU6574 | C4: 38 | D4: Male | E4: Mumbai | F4: Self-Employed | G4: 41793 | H4: 53625 | I4: 18 | J4: 14.32 | K4: 3328.25 | L4: Travel | M4: Defaulted | N4: 44606 | Q4: 770 | R4: Yes | S4: 25491.16 | T4: Feb-22 | U4: =COUNTIF(Table1[Loan_Status],"Defaulted")/COUNTA(Table1[Loan_ID]) -> 0.248
A5: LN0004 | B5: CU7201 | C5: 26 | D5: Female | E5: Chennai | F5: Self-Employed | G5: 65407 | H5: 374398 | I5: 3 | J5: 13.1 | K5: 127533.98 | L5: Medical | M5: Defaulted | N5: 44643 | Q5: 538 | R5: Yes | S5: 264526.63 | T5: Mar-22 | U5: =COUNTIF(Table1[Loan_Status],"Defaulted")/COUNTA(Table1[Loan_ID]) -> 0.248
A6: LN0005 | B6: CU7227 | C6: 38 | D6: Female | E6: Delhi | F6: Salaried | G6: 112040 | H6: 191264 | I6: 6 | J6: 28.08 | K6: 34538.39 | L6: Education | M6: Closed | N6: 45108 | O6: 2023-11-03 | P6: 125 | Q6: 467 | R6: No | S6: 0 | T6: Jul-23 | U6: =COUNTIF(Table1[Loan_Status],"Defaulted")/COUNTA(Table1[Loan_ID]) -> 0.248
A7: LN0006 | B7: CU5422 | C7: 35 | D7: Female | E7: Hyderabad | F7: Salaried | G7: 23414 | H7: 427075 | I7: 12 | J7: 21.63 | K7: 39895.81 | L7: Education | M7: Closed | N7: 45142 | O7: 2024-01-12 | P7: 161 | Q7: 517 | R7: No | S7: 0 | T7: Aug-23 | U7: =COUNTIF(Table1[Loan_Status],"Defaulted")/COUNTA(Table1[Loan_ID]) -> 0.248
A8: LN0007 | B8: CU7482 | C8: 50 | D8: Male | E8: Delhi | F8: Salaried | G8: 79651 | H8: 395588 | I8: 24 | J8: 24.94 | K8: 21101.23 | L8: Business | M8: Restructured | N8: 45159 | O8: 2024-03-12 | P8: 204 | Q8: 670 | R8: Yes | S8: 0 | T8: Aug-23 | U8: =COUNTIF(Table1[Loan_Status],"Defaulted")/COUNTA(Table1[Loan_ID]) -> 0.248
A9: LN0008 | B9: CU4593 | C9: 29 | D9: Female | E9: Hyderabad | F9: Salaried | G9: 43743 | H9: 85132 | I9: 6 | J9: 31.01 | K9: 15499.25 | L9: Shopping | M9: Active | N9: 44956 | Q9: 690 | R9: No | S9: 0 | T9: Jan-23 | U9: =COUNTIF(Table1[Loan_Status],"Defaulted")/COUNTA(Table1[Loan_ID]) -> 0.248
A10: LN0009 | B10: CU8668 | C10: 54 | D10: Female | E10: Chennai | F10: Salaried | G10: 45029 | H10: 362412 | I10: 24 | J10: 30.02 | K10: 20267.21 | L10: Travel | M10: Active | N10: 44862 | Q10: 745 | R10: No | S10: 0 | T10: Oct-22 | U10: =COUNTIF(Table1[Loan_Status],"Defaulted")/COUNTA(Table1[Loan_ID]) -> 0.248
A11: LN0010 | B11: CU1053 | C11: 37 | D11: Male | E11: Chennai | F11: Salaried | G11: 93235 | H11: 446277 | I11: 24 | J11: 26.62 | K11: 24182.76 | L11: Medical | M11: Defaulted | N11: 44727 | Q11: 843 | R11: Yes | S11: 331559.46 | T11: Jun-22 | U11: =COUNTIF(Table1[Loan_Status],"Defaulted")/COUNTA(Table1[Loan_ID]) -> 0.248
A12: LN0011 | B12: CU6310 | C12: 52 | D12: Male | E12: Hyderabad | F12: Self-Employed | G12: 95612 | H12: 130541 | I12: 3 | J12: 17.78 | K12: 44809.44 | L12: Business | M12: Active | N12: 44649 | Q12: 797 | R12: No | S12: 0 | T12: Mar-22 | U12: =COUNTIF(Table1[Loan_Status],"Defaulted")/COUNTA(Table1[Loan_ID]) -> 0.248
A13: LN0012 | B13: CU9727 | C13: 29 | D13: Male | E13: Bangalore | F13: Salaried | G13: 84483 | H13: 281653 | I13: 24 | J13: 22.16 | K13: 14633.9 | L13: Medical | M13: Closed | N13: 44881 | O13: 2023-12-29 | P13: 408 | Q13: 682 | R13: No | S13: 0 | T13: Nov-22 | U13: =COUNTIF(Table1[Loan_Status],"Defaulted")/COUNTA(Table1[Loan_ID]) -> 0.248
A14: LN0013 | B14: CU9479 | C14: 49 | D14: Male | E14: Mumbai | F14: Salaried | G14: 31784 | H14: 182254 | I14: 3 | J14: 26.12 | K14: 63415.02 | L14: Medical | M14: Closed | N14: 44569 | O14: 2022-03-21 | P14: 72 | Q14: 360 | R14: No | S14: 0 | T14: Jan-22 | U14: =COUNTIF(Table1[Loan_Status],"Defaulted")/COUNTA(Table1[Loan_ID]) -> 0.248
A15: LN0014 | B15: CU1514 | C15: 42 | D15: Male | E15: Chennai | F15: Salaried | G15: 88001 | H15: 355737 | I15: 18 | J15: 17.14 | K15: 22552.51 | L15: Medical | M15: Restructured | N15: 44810 | O15: 2024-01-03 | P15: 484 | Q15: 716 | R15: Yes | S15: 0 | T15: Sep-22 | U15: =COUNTIF(Table1[Loan_Status],"Defaulted")/COUNTA(Table1[Loan_ID]) -> 0.248
A16: LN0015 | B16: CU4119 | C16: 27 | D16: Male | E16: Bangalore | F16: Self-Employed | G16: 126038 | H16: 220535 | I16: 18 | J16: 32.73 | K16: 15667.68 | L16: Education | M16: Active | N16: 44624 | Q16: 712 | R16: No | S16: 0 | T16: Mar-22 | U16: =COUNTIF(Table1[Loan_Status],"Defaulted")/COUNTA(Table1[Loan_ID]) -> 0.248
A17: LN0016 | B17: CU2790 | C17: 36 | D17: Male | E17: Mumbai | F17: Self-Employed | G17: 51747 | H17: 226187 | I17: 6 | J17: 18.69 | K17: 39779.3 | L17: Medical | M17: Active | N17: 45015 | Q17: 400 | R17: Yes | S17: 0 | T17: Mar-23 | U17: =COUNTIF(Table1[Loan_Status],"Defaulted")/COUNTA(Table1[Loan_ID]) -> 0.248
A18: LN0017 | B18: CU9856 | C18: 21 | D18: Male | E18: Mumbai | F18: Salaried | G18: 121539 | H18: 259615 | I18: 18 | J18: 17.13 | K18: 16457.47 | L18: Shopping | M18: Active | N18: 44730 | Q18: 688 | R18: Yes | S18: 0 | T18: Jun-22 | U18: =COUNTIF(Table1[Loan_Status],"Defaulted")/COUNTA(Table1[Loan_ID]) -> 0.248
A19: LN0018 | B19: CU7396 | C19: 37 | D19: Female | E19: Delhi | F19: Self-Employed | G19: 142577 | H19: 86158 | I19: 6 | J19: 19.12 | K19: 15171 | L19: Education | M19: Active | N19: 44883 | Q19: 358 | R19: Yes | S19: 0 | T19: Nov-22 | U19: =COUNTIF(Table1[Loan_Status],"Defaulted")/COUNTA(Table1[Loan_ID]) -> 0.248
A20: LN0019 | B20: CU8811 | C20: 53 | D20: Male | E20: Hyderabad | F20: Salaried | G20: 63712 | H20: 40924 | I20: 24 | J20: 13.63 | K20: 1957.73 | L20: Medical | M20: Restructured | N20: 44684 | O20: 2023-12-07 | P20: 583 | Q20: 552 | R20: Yes | S20: 0 | T20: May-22 | U20: =COUNTIF(Table1[Loan_Status],"Defaulted")/COUNTA(Table1[Loan_ID]) -> 0.248
A21: LN0020 | B21: CU1651 | C21: 26 | D21: Female | E21: Chennai | F21: Self-Employed | G21: 83358 | H21: 112090 | I21: 12 | J21: 17.73 | K21: 10262.01 | L21: Shopping | M21: Closed | N21: 45249 | O21: 2024-05-02 | P21: 165 | Q21: 607 | R21: No | S21: 0 | T21: Nov-23 | U21: =COUNTIF(Table1[Loan_Status],"Defaulted")/COUNTA(Table1[Loan_ID]) -> 0.248
A22: LN0021 | B22: CU2188 | C22: 21 | D22: Female | E22: Chennai | F22: Salaried | G22: 34204 | H22: 286875 | I22: 6 | J22: 24.14 | K22: 51234.76 | L22: Medical | M22: Defaulted | N22: 44632 | Q22: 550 | R22: Yes | S22: 102893.16 | T22: Mar-22 | U22: =COUNTIF(Table1[Loan_Status],"Defaulted")/COUNTA(Table1[Loan_ID]) -> 0.248
A23: LN0022 | B23: CU3584 | C23: 49 | D23: Female | E23: Chennai | F23: Salaried | G23: 93480 | H23: 493508 | I23: 3 | J23: 34.53 | K23: 174059.31 | L23: Medical | M23: Defaulted | N23: 44680 | Q23: 409 | R23: Yes | S23: 305822.8 | T23: Apr-22 | U23: =COUNTIF(Table1[Loan_Status],"Defaulted")/COUNTA(Table1[Loan_ID]) -> 0.248
A24: LN0023 | B24: CU3546 | C24: 38 | D24: Female | E24: Chennai | F24: Salaried | G24: 104884 | H24: 111743 | I24: 12 | J24: 24.13 | K24: 10573.4 | L24: Travel | M24: Active | N24: 44656 | Q24: 733 | R24: No | S24: 0 | T24: Apr-22 | U24: =COUNTIF(Table1[Loan_Status],"Defaulted")/COUNTA(Table1[Loan_ID]) -> 0.248
A25: LN0024 | B25: CU1722 | C25: 21 | D25: Female | E25: Mumbai | F25: Self-Employed | G25: 57357 | H25: 393618 | I25: 18 | J25: 25.24 | K25: 26494.29 | L25: Shopping | M25: Active | N25: 44676 | Q25: 377 | R25: No | S25: 0 | T25: Apr-22 | U25: =COUNTIF(Table1[Loan_Status],"Defaulted")/COUNTA(Table1[Loan_ID]) -> 0.248
A26: LN0025 | B26: CU3442 | C26: 55 | D26: Male | E26: Delhi | F26: Salaried | G26: 127666 | H26: 71818 | I26: 3 | J26: 19.4 | K26: 24717.51 | L26: Education | M26: Defaulted | N26: 44777 | Q26: 555 | R26: Yes | S26: 40710.28 | T26: Aug-22 | U26: =COUNTIF(Table1[Loan_Status],"Defaulted")/COUNTA(Table1[Loan_ID]) -> 0.248
A27: LN0026 | B27: CU6794 | C27: 47 | D27: Male | E27: Mumbai | F27: Salaried | G27: 61413 | H27: 467115 | I27: 18 | J27: 12.59 | K27: 28613.82 | L27: Travel | M27: Restructured | N27: 45247 | O27: 2024-06-25 | P27: 221 | Q27: 554 | R27: Yes | S27: 0 | T27: Nov-23 | U27: =COUNTIF(Table1[Loan_Status],"Defaulted")/COUNTA(Table1[Loan_ID]) -> 0.248
A28: LN0027 | B28: CU5371 | C28: 31 | D28: Male | E28: Bangalore | F28: Salaried | G28: 138388 | H28: 121619 | I28: 6 | J28: 31.6 | K28: 22178.49 | L28: Shopping | M28: Defaulted | N28: 44874 | Q28: 533 | R28: Yes | S28: 31140.12 | T28: Nov-22 | U28: =COUNTIF(Table1[Loan_Status],"Defaulted")/COUNTA(Table1[Loan_ID]) -> 0.248
A29: LN0028 | B29: CU4164 | C29: 46 | D29: Female | E29: Delhi | F29: Salaried | G29: 88170 | H29: 189101 | I29: 24 | J29: 21.59 | K29: 9771.97 | L29: Business | M29: Defaulted | N29: 44590 | Q29: 418 | R29: Yes | S29: 135004.29 | T29: Jan-22 | U29: =COUNTIF(Table1[Loan_Status],"Defaulted")/COUNTA(Table1[Loan_ID]) -> 0.248
A30: LN0029 | B30: CU5279 | C30: 32 | D30: Female | E30: Hyderabad | F30: Salaried | G30: 128918 | H30: 186239 | I30: 12 | J30: 22.47 | K30: 17473.08 | L30: Business | M30: Active | N30: 44956 | Q30: 494 | R30: No | S30: 0 | T30: Jan-23 | U30: =COUNTIF(Table1[Loan_Status],"Defaulted")/COUNTA(Table1[Loan_ID]) -> 0.248
A31: LN0030 | B31: CU8144 | C31: 21 | D31: Male | E31: Delhi | F31: Self-Employed | G31: 33343 | H31: 353251 | I31: 12 | J31: 26.96 | K31: 33911.35 | L31: Education | M31: Defaulted | N31: 45081 | Q31: 616 | R31: Yes | S31: 200231.51 | T31: Jun-23 | U31: =COUNTIF(Table1[Loan_Status],"Defaulted")/COUNTA(Table1[Loan_ID]) -> 0.248
A32: LN0031 | B32: CU6344 | C32: 46 | D32: Female | E32: Chennai | F32: Salaried | G32: 65289 | H32: 225434 | I32: 18 | J32: 28.26 | K32: 15510.32 | L32: Medical | M32: Defaulted | N32: 44977 | Q32: 300 | R32: Yes | S32: 70496.02 | T32: Feb-23 | U32: =COUNTIF(Table1[Loan_Status],"Defaulted")/COUNTA(Table1[Loan_ID]) -> 0.248
A33: LN0032 | B33: CU4443 | C33: 48 | D33: Female | E33: Bangalore | F33: Self-Employed | G33: 130909 | H33: 359223 | I33: 6 | J33: 24.27 | K33: 64179.28 | L33: Medical | M33: Active | N33: 44852 | Q33: 827 | R33: No | S33: 0 | T33: Oct-22 | U33: =COUNTIF(Table1[Loan_Status],"Defaulted")/COUNTA(Table1[Loan_ID]) -> 0.248
A34: LN0033 | B34: CU6491 | C34: 26 | D34: Male | E34: Delhi | F34: Salaried | G34: 67200 | H34: 82255 | I34: 3 | J34: 13.11 | K34: 28019.59 | L34: Shopping | M34: Active | N34: 45028 | Q34: 724 | R34: No | S34: 0 | T34: Apr-23 | U34: =COUNTIF(Table1[Loan_Status],"Defaulted")/COUNTA(Table1[Loan_ID]) -> 0.248
A35: LN0034 | B35: CU4185 | C35: 45 | D35: Female | E35: Bangalore | F35: Salaried | G35: 53684 | H35: 348963 | I35: 3 | J35: 33.42 | K35: 122859.4 | L35: Education | M35: Restructured | N35: 44786 | O35: 2023-02-09 | P35: 180 | Q35: 830 | R35: Yes | S35: 0 | T35: Aug-22 | U35: =COUNTIF(Table1[Loan_Status],"Defaulted")/COUNTA(Table1[Loan_ID]) -> 0.248
A36: LN0035 | B36: CU8611 | C36: 24 | D36: Male | E36: Hyderabad | F36: Self-Employed | G36: 49954 | H36: 425173 | I36: 18 | J36: 28.02 | K36: 29202.07 | L36: Business | M36: Defaulted | N36: 45015 | Q36: 816 | R36: Yes | S36: 169524.35 | T36: Mar-23 | U36: =COUNTIF(Table1[Loan_Status],"Defaulted")/COUNTA(Table1[Loan_ID]) -> 0.248
A37: LN0036 | B37: CU9976 | C37: 49 | D37: Male | E37: Bangalore | F37: Self-Employed | G37: 82945 | H37: 399147 | I37: 6 | J37: 32.16 | K37: 72901.96 | L37: Travel | M37: Restructured | N37: 45203 | O37: 2024-02-03 | P37: 122 | Q37: 581 | R37: Yes | S37: 0 | T37: Oct-23 | U37: =COUNTIF(Table1[Loan_Status],"Defaulted")/COUNTA(Table1[Loan_ID]) -> 0.248
A38: LN0037 | B38: CU8206 | C38: 25 | D38: Female | E38: Mumbai | F38: Self-Employed | G38: 103040 | H38: 172619 | I38: 24 | J38: 13.93 | K38: 8282.23 | L38: Medical | M38: Closed | N38: 44954 | O38: 2023-07-03 | P38: 156 | Q38: 519 | R38: Yes | S38: 0 | T38: Jan-23 | U38: =COUNTIF(Table1[Loan_Status],"Defaulted")/COUNTA(Table1[Loan_ID]) -> 0.248
A39: LN0038 | B39: CU7678 | C39: 42 | D39: Female | E39: Bangalore | F39: Salaried | G39: 69220 | H39: 441674 | I39: 18 | J39: 21.35 | K39: 28891.66 | L39: Business | M39: Active | N39: 45151 | Q39: 689 | R39: No | S39: 0 | T39: Aug-23 | U39: =COUNTIF(Table1[Loan_Status],"Defaulted")/COUNTA(Table1[Loan_ID]) -> 0.248
A40: LN0039 | B40: CU6763 | C40: 40 | D40: Female | E40: Bangalore | F40: Salaried | G40: 142986 | H40: 120040 | I40: 12 | J40: 22.46 | K40: 11261.66 | L40: Education | M40: Restructured | N40: 44906 | O40: 2024-01-29 | P40: 414 | Q40: 469 | R40: Yes | S40: 0 | T40: Dec-22 | U40: =COUNTIF(Table1[Loan_Status],"Defaulted")/COUNTA(Table1[Loan_ID]) -> 0.248
...

Sheet KPI
A1: KPI | B1: Value | C1: value out of pivot table
A2: Total Loans | B2: =COUNTA('Raw Data'!A2:A501) -> 500 | C2: =B2 -> 500
A3: Total Disbursed (₹) | B3: =SUM('Raw Data'!H2:H501) -> 121212530 | C3: =B3 -> 121212530
A4: Total EMI Collected (₹) | B4: =SUM('Raw Data'!K2:K501) -> 16397630 | C4: =B4 -> 16397630
A5: Active Loans | B5: =COUNTIF('Raw Data'!M2:M501,"Active") -> 128 | C5: =B5 -> 128
A6: Closed Loans | B6: =COUNTIF('Raw Data'!M2:M501,"Closed") -> 127 | C6: =B6 -> 127
A7: Defaulted Loans | B7: =COUNTIF('Raw Data'!M2:M501,"Defaulted") -> 124 | C7: =B7 -> 124
A8: Restructured Loans | B8: =COUNTIF('Raw Data'!M2:M501,"Restructured") -> 121 | C8: =B8 -> 121
A9: Default Rate (%) | B9: =COUNTIF('Raw Data'!M2:M501,"Defaulted")/COUNTA('Raw Data'!A2:A501) -> 0.248 | C9: =B9 -> 0.248
A10: Avg Loan Amount (₹) | B10: =AVERAGE('Raw Data'!H2:H501) -> 242425.06 | C10: =B10 -> 242425.06
A11: Avg EMI (₹) | B11: =AVERAGE('Raw Data'!K2:K501) -> 32795.261 | C11: =B11 -> 32795.261
A12: Avg Credit Score | B12: =AVERAGE('Raw Data'!Q2:Q501) -> 573.4 | C12: =B12 -> 573.4
A13: Avg Interest Rate (%) | B13: =AVERAGE('Raw Data'!J2:J501)/100 -> 0.2417106 | C13: =B13 -> 0.2417106
A14: Avg Tenure (Months) | B14: =AVERAGE('Raw Data'!I2:I501) -> 13.29 | C14: =B14 -> 13.29
A15: Total Recovery (₹) | B15: =SUM('Raw Data'!S2:S501) -> 14439288 | C15: =B15 -> 14439288
A16: Recovery Rate (%) | B16: =SUM('Raw Data'!S2:S501)/SUMIF('Raw Data'!M2:M501,"Defaulted",'Raw Data'!H2:H501) -> 0.46945937 | C16: =B16 -> 0.46945937
A17: DPD 30+ Count | B17: =COUNTIF('Raw Data'!R2:R501,"Yes") -> 280 | C17: =B17 -> 280
A20: Total Loans Applications | B20: Total Disbursment Amt | C20: Total Amount Recovered | D20: Average Credit Score | E20: Average EMI | F20: Average Default Rate
A21: Count of Loan_ID | B21: Sum of Loan_Amount | C21: Sum of Recovery_Amount | D21: Average of Credit_Score | E21: Average of EMI_Amount | F21: Average of Default Interest Rate
A22: 500 | B22: 121212530 | C22: 14439288 | D22: 573.4 | E22: 32795.261 | F22: 0.248
A23: =GETPIVOTDATA("Count of Loan_ID",$A$21) -> 500 | B23: =GETPIVOTDATA("Sum of Loan_Amount",$A$21) -> 121212530 | C23: =GETPIVOTDATA("Sum of Recovery_Amount",$A$21) -> 14439288 | D23: =GETPIVOTDATA("Average of Credit_Score",$A$21) -> 573.4 | E23: =GETPIVOTDATA("Average of EMI_Amount",$A$21) -> 32795.261 | F23: =GETPIVOTDATA("Average of Default Interest Rate",$A$21) -> 0.248
A26: MTD Measure
B27: Total Loans Applications | C27: Total Disbursment Amt | D27: Total Amount Recovered | E27: Average Credit Score | F27: Average EMI | G27: Average Default Rate
A28: Row Labels | B28: Count of Loan_ID | C28: Sum of Loan_Amount | D28: Sum of Recovery_Amount | E28: Average of Credit_Score | F28: Average of EMI_Amount | G28: Average of Default Interest Rate | I28: MOM = (MTD-PMTD)/PMTD
A29: Dec | B29: 36 | C29: 7799479 | D29: 1001646.9 | E29: 514.66667 | F29: 38760.603 | G29: 0.248
A30: =A29 -> Dec | B30: =GETPIVOTDATA("Count of Loan_ID",$A$28,"Months (Disbursement_Date)",12) -> 36 | C30: =GETPIVOTDATA("Sum of Loan_Amount",$A$28,"Months (Disbursement_Date)",12) -> 7799479 | D30: =GETPIVOTDATA("Sum of Recovery_Amount",$A$28,"Months (Disbursement_Date)",12) -> 1001646.9 | E30: =GETPIVOTDATA("Average of Credit_Score",$A$28,"Months (Disbursement_Date)",12) -> 514.66667 | F30: =GETPIVOTDATA("Average of EMI_Amount",$A$28,"Months (Disbursement_Date)",12) -> 38760.603 | G30: =GETPIVOTDATA("Average of Default Interest Rate",$A$28,"Months (Disbursement_Date)",12) -> 0.248
A32: PMTD Measure
B33: Total Loans Applications | C33: Total Disbursment Amt | D33: Total Amount Recovered | E33: Average Credit Score | F33: Average EMI | G33: Average Default Rate
A34: Row Labels | B34: Count of Loan_ID | C34: Sum of Loan_Amount | D34: Sum of Recovery_Amount | E34: Average of Credit_Score | F34: Average of EMI_Amount | G34: Average of Default Interest Rate
A35: Nov | B35: 51 | C35: 12472037 | D35: 1031337.5 | E35: 543.7451 | F35: 25055.157 | G35: 0.248
B36: =GETPIVOTDATA("Count of Loan_ID",$A$34,"Months (Disbursement_Date)",11) -> 51 | C36: =GETPIVOTDATA("Sum of Loan_Amount",$A$34,"Months (Disbursement_Date)",11) -> 12472037 | D36: =GETPIVOTDATA("Sum of Recovery_Amount",$A$34,"Months (Disbursement_Date)",11) -> 1031337.5 | E36: =GETPIVOTDATA("Average of Credit_Score",$A$34,"Months (Disbursement_Date)",11) -> 543.7451 | F36: =GETPIVOTDATA("Average of EMI_Amount",$A$34,"Months (Disbursement_Date)",11) -> 25055.157 | G36: =GETPIVOTDATA("Average of Default Interest Rate",$A$34,"Months (Disbursement_Date)",11) -> 0.248
A38: MOM Measure
B39: Total Loans Applications | C39: Total Disbursment Amt | D39: Total Amount Recovered | E39: Average Credit Score | F39: Average EMI | G39: Average Default Rate
B40: =(GETPIVOTDATA("Count of Loan_ID",$A$28,"Months (Disbursement_Date)",12)-GETPIVOTDATA("Count of Loan_ID",$A$34,"Months (Disbursement_Date)",11))/GETPIVOTDATA("Count of Loan_ID",$A$34,"Months (Disbursement_Date)",11) -> -0.29411765 | C40: =(GETPIVOTDATA("Sum of Loan_Amount",$A$28,"Months (Disbursement_Date)",12)-GETPIVOTDATA("Sum of Loan_Amount",$A$34,"Months (Disbursement_Date)",11))/GETPIVOTDATA("Sum of Loan_Amount",$A$34,"Months (Disbursement_Date)",11) -> -0.37464273 | D40: =(GETPIVOTDATA("Sum of Recovery_Amount",$A$28,"Months (Disbursement_Date)",12)-GETPIVOTDATA("Sum of Recovery_Amount",$A$34,"Months (Disbursement_Date)",11))/GETPIVOTDATA("Sum of Recovery_Amount",$A$34,"Months (Disbursement_Date)",11) -> -0.028788461 | E40: =(GETPIVOTDATA("Average of Credit_Score",$A$28,"Months (Disbursement_Date)",12)-GETPIVOTDATA("Average of Credit_Score",$A$34,"Months (Disbursement_Date)",11))/GETPIVOTDATA("Average of Credit_Score",$A$34,"Months (Disbursement_Date)",11) -> -0.053478057 | F40: =(GETPIVOTDATA("Average of EMI_Amount",$A$28,"Months (Disbursement_Date)",12)-GETPIVOTDATA("Average of EMI_Amount",$A$34,"Months (Disbursement_Date)",11))/GETPIVOTDATA("Average of EMI_Amount",$A$34,"Months (Disbursement_Date)",11) -> 0.54701097 | G40: 0.248

Sheet Pivot Tables
A1: Row Labels | B1: Count of Loan_ID
A2: Active | B2: 128
A3: Closed | B3: 127
A4: Defaulted | B4: 124
A5: Restructured | B5: 121
A6: Grand Total | B6: 500
A10: Row Labels | B10: Sum of Loan_Amount
A11: Business | B11: 27542872
A12: Education | B12: 26056082
A13: Travel | B13: 24263898
A14: Medical | B14: 23346728
A15: Shopping | B15: 20002950
A16: Grand Total | B16: 121212530
A19: Loan_Status | B19: (All)
A21: Row Labels | B21: Count of Loan_ID
A22: Bangalore | B22: 108
A23: Delhi | B23: 106
A24: Chennai | B24: 100
A25: Hyderabad | B25: 97
A26: Mumbai | B26: 89
A29: Sum of Loan_Amount | B29: Column Labels
A30: Row Labels | B30: 3 | C30: 6 | D30: 12 | E30: 18 | F30: 24
A31: Salaried | B31: 11067930 | C31: 11640202 | D31: 11187171 | E31: 13268344 | F31: 14364706
A32: Self-Employed | B32: 8692861 | C32: 11075457 | D32: 11103937 | E32: 13932716 | F32: 14879206
A35: Disbursment Month | B35: Sum of Loan_Amount
A36: Apr-22 | B36: 5427241
A37: Apr-23 | B37: 6141576
A38: Aug-22 | B38: 3451968
A39: Aug-23 | B39: 9371827
A40: Dec-22 | B40: 3404028
A41: Dec-23 | B41: 4395451
A42: Feb-22 | B42: 4338910
A43: Feb-23 | B43: 5852558
A44: Jan-22 | B44: 3062967
A45: Jan-23 | B45: 4208620
A46: Jul-22 | B46: 4163921
A47: Jul-23 | B47: 4331510
... A60: Grand Total | B60: 121212530

Sheet Charts

Sheet DashBoard Layout
B2: LOAN DISBURSMENT PORTFOLIO DASHBOARD
